<?xml version="1.0"?>
<robot xmlns:xacro="http://www.ros.org/wiki/xacro" name="mon_robot">

  <xacro:macro name="inertial_box" params="mass x y z *origin">
    <inertial>
      <xacro:insert_block name="origin"/>
      <mass value="${mass}" />
      <inertia ixx="${(1/12) * mass * (y*y+z*z)}" ixy="0.0" ixz="0.0"
               iyy="${(1/12) * mass * (x*x+z*z)}" iyz="0.0"
               izz="${(1/12) * mass * (x*x+y*y)}" />
    </inertial>
  </xacro:macro>

  <xacro:macro name="inertial_cylinder" params="mass length radius *origin">
    <inertial>
      <xacro:insert_block name="origin"/>
      <mass value="${mass}" />
      <inertia ixx="${(1/12) * mass * (3*radius*radius + length*length)}" ixy="0.0" ixz="0.0"
               iyy="${(1/12) * mass * (3*radius*radius + length*length)}" iyz="0.0"
               izz="${(1/2) * mass * (radius*radius)}" />
    </inertial>
  </xacro:macro>

  <material name="blue"><color rgba="0 0 0.8 1"/></material>
  <material name="black"><color rgba="0 0 0 1"/></material>

  <link name="base_link"></link>

  <joint name="chassis_joint" type="fixed">
    <parent link="base_link"/>
    <child link="chassis"/>
    <origin xyz="-0.3 0 0"/>
  </joint>

  <link name="chassis">
    <visual>
      <origin xyz="0.3 0 0.075"/>
      <geometry><box size="0.9 0.9 0.15"/></geometry>
      <material name="blue"/>
    </visual>
    <collision>
      <origin xyz="0.3 0 0.075"/>
      <geometry><box size="0.9 0.9 0.15"/></geometry>
    </collision>
    <xacro:inertial_box mass="0.5" x="0.9" y="0.9" z="0.15">
        <origin xyz="0.3 0 0.015" rpy="0 0 0"/>
    </xacro:inertial_box>
  </link>

  <xacro:macro name="wheel" params="prefix x_reflect y_reflect">
    <link name="${prefix}_link">
      <visual>
        <geometry><cylinder radius="0.15" length="0.12"/></geometry>
        <material name="black"/>
      </visual>
      <collision>
        <geometry><cylinder radius="0.15" length="0.12"/></geometry>
      </collision>
      <xacro:inertial_cylinder mass="0.1" length="0.12" radius="0.15">
        <origin xyz="0 0 0" rpy="0 0 0"/>
      </xacro:inertial_cylinder>
    </link>

    <joint name="${prefix}_joint" type="continuous">
      <parent link="base_link"/>
      <child link="${prefix}_link"/>
      <origin xyz="${x_reflect*0.3} ${y_reflect*0.525} 0" rpy="-1.57 0 0"/>
      <axis xyz="0 0 1"/>
    </joint>
  </xacro:macro>

  <xacro:wheel prefix="front_left" x_reflect="1" y_reflect="1" />
  <xacro:wheel prefix="front_right" x_reflect="1" y_reflect="-1" />
  <xacro:wheel prefix="rear_left" x_reflect="-1" y_reflect="1" />
  <xacro:wheel prefix="rear_right" x_reflect="-1" y_reflect="-1" />

  <link name="arm_1_link">
    <visual>
      <origin xyz="0 0 0.3" rpy="0 0 0"/>
      <geometry><box size="0.15 0.15 0.6"/></geometry>
      <material name="orange"><color rgba="1 0.5 0 1"/></material>
    </visual>
    <collision>
      <origin xyz="0 0 0.3" rpy="0 0 0"/>
      <geometry><box size="0.15 0.15 0.6"/></geometry>
    </collision>
    <xacro:inertial_box mass="0.1" x="0.15" y="0.15" z="0.6">
      <origin xyz="0 0 0.3" rpy="0 0 0"/>
    </xacro:inertial_box>
  </link>

  <joint name="shoulder_joint" type="revolute">
    <parent link="chassis"/>
    <child link="arm_1_link"/>
    <origin xyz="0.3 0 0.15" rpy="0 0 0"/>
    <axis xyz="0 1 0"/> <limit lower="-1.57" upper="1.57" effort="10" velocity="1"/>
    <dynamics damping="0.1" friction="0.1"/> 
  </joint>

  <link name="arm_2_link">
    <visual>
      <origin xyz="0 0 0.3" rpy="0 0 0"/>
      <geometry><box size="0.12 0.12 0.6"/></geometry>
      <material name="orange"/>
    </visual>
    <collision>
      <origin xyz="0 0 0.3" rpy="0 0 0"/>
      <geometry><box size="0.12 0.12 0.6"/></geometry>
    </collision>
    <xacro:inertial_box mass="0.1" x="0.12" y="0.12" z="0.6">
      <origin xyz="0 0 0.3" rpy="0 0 0"/>
    </xacro:inertial_box>
  </link>

  <joint name="elbow_joint" type="revolute">
    <parent link="arm_1_link"/>
    <child link="arm_2_link"/>
    <origin xyz="0 0 0.6" rpy="0 0 0"/> <axis xyz="0 1 0"/>
    <limit lower="-2.5" upper="2.5" effort="10" velocity="1"/>
    <dynamics damping="0.1" friction="0.1"/>
  </joint>

  <ros2_control name="GazeboSystem" type="system">
    <hardware>
      <plugin>gazebo_ros2_control/GazeboSystem</plugin>
    </hardware>
    
    <xacro:macro name="control_joint" params="name">
      <joint name="${name}">
        <command_interface name="velocity">
          <param name="min">-10</param>
          <param name="max">10</param>
        </command_interface>
        <state_interface name="position"/>
        <state_interface name="velocity"/>
      </joint>
    </xacro:macro>

    <joint name="shoulder_joint">
        <command_interface name="position"/>
        <state_interface name="position"/>
        <state_interface name="velocity"/>
    </joint>
    <joint name="elbow_joint">
        <command_interface name="position"/>
        <state_interface name="position"/>
        <state_interface name="velocity"/>
    </joint>

    <xacro:control_joint name="front_left_joint"/>
    <xacro:control_joint name="front_right_joint"/>
    <xacro:control_joint name="rear_left_joint"/>
    <xacro:control_joint name="rear_right_joint"/>
  </ros2_control>

  <gazebo>
    <plugin name="gazebo_ros2_control" filename="libgazebo_ros2_control.so">
      <parameters>$(find my_robot_controller)/config/my_controllers.yaml</parameters>
    </plugin>
  </gazebo>

</robot>